Workbook

Sheet Sample14-Manual annotation
A1: Field | B1: sample14- values from the PDF
B2: Item 1 | C2: Item 2 | D2: Item 3 | E2: Item 4 | F2: Item 5 | G2: Item 6 | H2: Item 7 | I2: Item 8 | J2: Item 9 | K2: Item 10 | L2: Item 11
A3: $
A4: dmp
A5: dmp.title | B5: Hakai Institute Juvenile Salmon Program Time Series
A6: dmp.description
A7: dmp.dmp_id
A8: dmp.dmp_id.identifier | B8: https://doi.org/10.48321/D1CW23
A9: dmp.dmp_id.type | B9: doi
A10: dmp.created | B10: 2015-05-12T00:00:00Z
A11: dmp.modified | B11: 2024-06-11T00:00:00Z
A12: dmp.ethical_issues_exist | B12: no
A13: dmp.ethical_issues_description
A14: dmp.ethical_issues_report
A15: dmp.language | B15: eng
A16: dmp.contact
A17: dmp.contact.name | B17: Brett Johnson
A18: dmp.contact.mbox
A19: dmp.contact.affiliation
A20: dmp.contact.affiliation[]
A21: dmp.contact.affiliation[].name | B21: Hakai Institute
A22: dmp.contact.affiliation[].affiliation_id
A23: dmp.contact.affiliation[].affiliation_id.identifier
A24: dmp.contact.affiliation[].affiliation_id.type
A25: dmp.contact.contact_id
A26: dmp.contact.contact_id[]
A27: dmp.contact.contact_id[].identifier | B27: 0000-0001-9317-0364
A28: dmp.contact.contact_id[].type | B28: orcid
A29: dmp.contributor
A30: dmp.contributor[]
A31: dmp.contributor[].name | B31: Brett Johnson | C31: Brian Hunt | D31: Tim van der Stap | E31: Krystal Bachen
A32: dmp.contributor[].contributor_id
A33: dmp.contributor[].contributor_id[]
A34: dmp.contributor[].contributor_id[].identifier
A35: dmp.contributor[].contributor_id[].type
A36: dmp.contributor[].affiliation
A37: dmp.contributor[].affiliation[]
A38: dmp.contributor[].affiliation[].name
A39: dmp.contributor[].affiliation[].affiliation_id
A40: dmp.contributor[].affiliation[].affiliation_id.identifier
...

Sheet Reference (JSON)
A1: Field | B1: Value
A2: dmp.title | B2: Hakai Institute Juvenile Salmon Program Time Series
A3: dmp.dmp_id.identifier | B3: https://doi.org/10.48321/D1CW23
A4: dmp.dmp_id.type | B4: doi
A5: dmp.created | B5: 2015-05-12T00:00:00Z
A6: dmp.modified | B6: 2024-06-11T00:00:00Z
A7: dmp.ethical_issues_exist | B7: no
A8: dmp.language | B8: eng
A9: dmp.contact.name | B9: Brett Johnson
A10: dmp.contact.affiliation[0].name | B10: Hakai Institute
A11: dmp.contact.contact_id[0].identifier | B11: 0000-0001-9317-0364
A12: dmp.contact.contact_id[0].type | B12: orcid
... A135: dmp.project[0].funding[0].name | B135: Tula Foundation
A137: Source: RDA_DMP_sample14_manual_annotation.json, every field with a value (134 fields). Listed by notebooks/evaluate-rda-json.ipynb on 2026-10-02.

Sheet sample14-llama3.1-8b
A1: Field | B1: Value | C1: Ground truth | D1: Verdict | E1: Notes
A2: dmp.contact.contact_id[0].identifier | B2: 0000-0001-9317-0364 | C2: 0000-0001-9317-0364 | D2: Correct
A3: dmp.contact.contact_id[0].type | B3: orcid | C3: orcid | D3: Correct
A4: dmp.contact.mbox | B4: brett.johnson@hakai.org | D4: Hallucinated | E4: not in the reference
A5: dmp.contact.name | B5: Brett Johnson | C5: Brett Johnson | D5: Correct
A6: dmp.created | B6: 2015-05-12T00:00:00Z | C6: 2015-05-12T00:00:00Z | D6: Correct
A7: dmp.dataset[0].dataset_id.identifier | B7: https://doi.org/10.48321/D1CW23 | C7: https://doi.org/10.21966/1.566666 | D7: Hallucinated | E7: identifier differs
A8: dmp.dataset[0].dataset_id.type | B8: doi | C8: doi | D8: Correct
A9: dmp.dataset[0].personal_data | B9: no | C9: no | D9: Correct
A10: dmp.dataset[0].sensitive_data | B10: no | C10: no | D10: Correct
A11: dmp.dataset[0].title | B11: Hakai Institute Juvenile Salmon Program Time Series | C11: Hakai Institute Juvenile Salmon Program Time Series | D11: Correct
A12: dmp.dataset[0].type | B12: dataset | C12: dataset | D12: Correct
A13: dmp.dmp_id.identifier | B13: https://doi.org/10.48321/D1CW23 | C13: https://doi.org/10.48321/D1CW23 | D13: Correct
A14: dmp.dmp_id.type | B14: doi | C14: doi | D14: Correct
A15: dmp.ethical_issues_exist | B15: no | C15: no | D15: Correct
A16: dmp.language | B16: eng | C16: eng | D16: Correct
A17: dmp.modified | B17: 2024-06-11T00:00:00Z | C17: 2024-06-11T00:00:00Z | D17: Correct
A18: dmp.title | B18: Hakai Institute Juvenile Salmon Program Time Series | C18: Hakai Institute Juvenile Salmon Program Time Series | D18: Correct
A19: dmp.contact.affiliation[0].name | C19: Hakai Institute | D19: Missed
A20: dmp.contributor[0].name | C20: Brett Johnson | D20: Missed
A21: dmp.contributor[0].role[0] | C21: Principal Investigator | D21: Missed
A22: dmp.contributor[0].role[1] | C22: Data Manager | D22: Missed
A23: dmp.contributor[1].name | C23: Brian Hunt | D23: Missed
A24: dmp.contributor[1].role[0] | C24: Principal Investigator | D24: Missed
A25: dmp.contributor[2].name | C25: Tim van der Stap | D25: Missed
A26: dmp.contributor[2].role[0] | C26: Data Manager | D26: Missed
A27: dmp.contributor[3].name | C27: Krystal Bachen | D27: Missed
A28: dmp.contributor[3].role[0] | C28: Data Manager | D28: Missed
A29: dmp.dataset[0].dataset_id.identifier | C29: https://doi.org/10.21966/1.566666 | D29: Missed
A30: dmp.dataset[0].description | C30: The core of the Hakai JSP are the observations made at sea during seining operations, and the observations and measurements made in the lab during fish dissections. Many samples are produced from fish that are collected in the lab, and those data may be addressed in their own Data Management Plans. | D30: Missed
... A137: dmp.related_identifier[0].identifier | C137: https://doi.org/10.26428/1606-9919-2021-201-669-685 | D137: Missed

Sheet sample14-gemma4-e4b
A1: Field | B1: Value | C1: Ground truth | D1: Verdict | E1: Notes
A2: dmp.contact.contact_id[0].identifier | B2: 0000-0003-0644-4174 | C2: 0000-0001-9317-0364 | D2: Hallucinated | E2: identifier differs
A3: dmp.contact.contact_id[0].type | B3: orcid | C3: orcid | D3: Correct
A4: dmp.contact.mbox | D4: Correct | E4: both empty
A5: dmp.contact.name | C5: Brett Johnson | D5: Hallucinated | E5: empty where the reference has a value
A6: dmp.created | B6: 2024-06-11T00:00:00Z | C6: 2015-05-12T00:00:00Z | D6: Hallucinated | E6: different day
A7: dmp.dataset[0].dataset_id.identifier | B7: www.github.com/hakaiinstitute/jsp-data | C7: https://doi.org/10.21966/1.566666 | D7: Hallucinated | E7: identifier differs
A8: dmp.dataset[0].dataset_id.type | B8: url | C8: doi | D8: Hallucinated | E8: different value
A9: dmp.dataset[0].personal_data | B9: unknown | C9: no | D9: Hallucinated | E9: different value
A10: dmp.dataset[0].sensitive_data | B10: unknown | C10: no | D10: Hallucinated | E10: different value
A11: dmp.dataset[0].title | B11: Hakai JSP Time Series | C11: Hakai Institute Juvenile Salmon Program Time Series | D11: Correct
A12: dmp.dataset[0].type | B12: raw data | C12: dataset | D12: Hallucinated | E12: different value
A13: dmp.dataset[1].dataset_id.identifier | B13: https://doi.org/10.21966/1.566666 | D13: Hallucinated | E13: not in the reference
A14: dmp.dataset[1].dataset_id.type | B14: image | D14: Hallucinated | E14: not in the reference
A15: dmp.dataset[1].personal_data | B15: unknown | C15: no | D15: Hallucinated | E15: different value
A16: dmp.dataset[1].sensitive_data | B16: unknown | C16: no | D16: Hallucinated | E16: different value
A17: dmp.dataset[1].title | B17: Juvenile Salmon Program Time Series | C17: Fatty acids from juvenile salmon | D17: Hallucinated | E17: only 40% of the model's words are in the reference
A18: dmp.dataset[1].type | B18: image | C18: dataset | D18: Hallucinated | E18: different value
A19: dmp.dmp_id.identifier | B19: https://doi.org/10.48321/D1CW23 | C19: https://doi.org/10.48321/D1CW23 | D19: Correct
A20: dmp.dmp_id.type | B20: doi | C20: doi | D20: Correct
A21: dmp.ethical_issues_exist | B21: unknown | C21: no | D21: Hallucinated | E21: different value
A22: dmp.language | B22: eng | C22: eng | D22: Correct
A23: dmp.modified | B23: 2024-06-11T00:00:00Z | C23: 2024-06-11T00:00:00Z | D23: Correct
A24: dmp.title | B24: Hakai Institute Juvenile Salmon Program Time Series | C24: Hakai Institute Juvenile Salmon Program Time Series | D24: Correct
A25: dmp.contact.affiliation[0].name | C25: Hakai Institute | D25: Missed
A26: dmp.contact.contact_id[0].identifier | C26: 0000-0001-9317-0364 | D26: Missed
A27: dmp.contact.name | C27: Brett Johnson | D27: Missed
A28: dmp.contributor[0].name | C28: Brett Johnson | D28: Missed
A29: dmp.contributor[0].role[0] | C29: Principal Investigator | D29: Missed
A30: dmp.contributor[0].role[1] | C30: Data Manager | D30: Missed
A31: dmp.contributor[1].name | C31: Brian Hunt | D31: Missed
A32: dmp.contributor[1].role[0] | C32: Principal Investigator | D32: Missed
A33: dmp.contributor[2].name | C33: Tim van der Stap | D33: Missed
A34: dmp.contributor[2].role[0] | C34: Data Manager | D34: Missed
A35: dmp.contributor[3].name | C35: Krystal Bachen | D35: Missed
A36: dmp.contributor[3].role[0] | C36: Data Manager | D36: Missed
... A151: dmp.related_identifier[0].identifier | C151: https://doi.org/10.26428/1606-9919-2021-201-669-685 | D151: Missed

Sheet sample14-version1-llama3.3-70b
A1: Field | B1: Value | C1: Ground truth | D1: Verdict | E1: Notes
A2: dmp.contact.affiliation[0].affiliation_id.identifier | B2: https://www.hakai.org/ | D2: Hallucinated | E2: not in the reference
A3: dmp.contact.affiliation[0].affiliation_id.type | B3: url | D3: Hallucinated | E3: not in the reference
A4: dmp.contact.affiliation[0].name | B4: Hakai Institute | C4: Hakai Institute | D4: Correct
A5: dmp.contact.contact_id[0].identifier | B5: 0000-0001-9317-0364 | C5: 0000-0001-9317-0364 | D5: Correct
A6: dmp.contact.contact_id[0].type | B6: orcid | C6: orcid | D6: Correct
A7: dmp.contact.mbox | B7: brett.johnson@hakai.org | D7: Hallucinated | E7: not in the reference
A8: dmp.contact.name | B8: Brett Johnson | C8: Brett Johnson | D8: Correct
A9: dmp.created | B9: 2015-05-12T00:00:00Z | C9: 2015-05-12T00:00:00Z | D9: Correct
A10: dmp.dataset[0].dataset_id.identifier | B10: https://doi.org/10.21966/1.566666 | C10: https://doi.org/10.21966/1.566666 | D10: Correct
A11: dmp.dataset[0].dataset_id.type | B11: doi | C11: doi | D11: Correct
A12: dmp.dataset[0].description | B12: The Hakai Institute Juvenile Salmon program is an ongoing initiative that was established in 2015 in partnership with the University of British Columbia, University of Toronto, Simon Fraser University and Salmon Coast Field Station. | C12: The core of the Hakai JSP are the observations made at sea during seining operations, and the observations and measurements made in the lab during fish dissections. Many samples are produced from fish that are collected in the lab, and those data may be addressed in their own Data Management Plans. | D12: Hallucinated | E12: only 21% of the model's words are in the reference
A13: dmp.dataset[0].distribution[0].data_access | B13: open | C13: open | D13: Correct
A14: dmp.dataset[0].distribution[0].description | B14: Core observations made in the field and from lab dissections conducted by Hakai staff including species counts, fork lengths, and weights | D14: Hallucinated | E14: not in the reference
A15: dmp.dataset[0].distribution[0].license[0].license_ref | B15: https://creativecommons.org/licenses/by/4.0/ | C15: CC BY 4.0 | D15: Correct
A16: dmp.dataset[0].distribution[0].license[0].start_date | B16: 2020-01-01 | D16: Hallucinated | E16: not in the reference
A17: dmp.dataset[0].distribution[0].title | B17: Hakai JSP Time Series | C17: Hakai JSP Time Series | D17: Correct
A18: dmp.dataset[0].personal_data | B18: no | C18: no | D18: Correct
A19: dmp.dataset[0].sensitive_data | B19: no | C19: no | D19: Correct
A20: dmp.dataset[0].title | B20: Hakai Institute Juvenile Salmon Program Time Series | C20: Hakai Institute Juvenile Salmon Program Time Series | D20: Correct
A21: dmp.dataset[1].dataset_id.identifier | B21: https://doi.org/10.26428/1606-9919-2021-201-669-685 | D21: Hallucinated | E21: not in the reference
A22: dmp.dataset[1].dataset_id.type | B22: doi | D22: Hallucinated | E22: not in the reference
A23: dmp.dataset[1].description | B23: Microchemistry data as obtained from otolith analysis. Otoliths were obtained from juvenile salmon as part of the Juvenile Salmon Program (JSP). | C23: Microchemistry data as obtained from otolith analysis. Otoliths were obtained from juvenile salmon as part of the Juvenile Salmon Program (JSP). The responsible party for this dataset is Yuliya Kuzmenko (UBC). The Paper has been published at https://doi.org/10.26428/1606-9919-2021-201-669-685 but we need to reach out to Yuliya to collect data. | D23: Correct
A24: dmp.dataset[1].personal_data | B24: no | C24: no | D24: Correct
A25: dmp.dataset[1].sensitive_data | B25: no | C25: no | D25: Correct
A26: dmp.dataset[1].title | B26: Otolith Microchemistry from juvenile sockeye | C26: Otolith Microchemistry from juvenile sockeye | D26: Correct
A27: dmp.dmp_id.identifier | B27: https://doi.org/10.48321/D1CW23 | C27: https://doi.org/10.48321/D1CW23 | D27: Correct
A28: dmp.dmp_id.type | B28: doi | C28: doi | D28: Correct
A29: dmp.ethical_issues_exist | B29: no | C29: no | D29: Correct
A30: dmp.language | B30: eng | C30: eng | D30: Correct
A31: dmp.modified | B31: 2024-06-11T00:00:00Z | C31: 2024-06-11T00:00:00Z | D31: Correct
A32: dmp.title | B32: Hakai Institute Juvenile Salmon Program Time Series | C32: Hakai Institute Juvenile Salmon Program Time Series | D32: Correct
A33: dmp.contributor[0].name | C33: Brett Johnson | D33: Missed
A34: dmp.contributor[0].role[0] | C34: Principal Investigator | D34: Missed
A35: dmp.contributor[0].role[1] | C35: Data Manager | D35: Missed
A36: dmp.contributor[1].name | C36: Brian Hunt | D36: Missed
A37: dmp.contributor[1].role[0] | C37: Principal Investigator | D37: Missed
A38: dmp.contributor[2].name | C38: Tim van der Stap | D38: Missed
A39: dmp.contributor[2].role[0] | C39: Data Manager | D39: Missed
A40: dmp.contributor[3].name | C40: Krystal Bachen | D40: Missed
...

Sheet summary
A1: Correct / Hallucinated / Missed per model : sample14, scored against the manual annotation
A3: Metric | B3: llama3.1-8b | C3: gemma4-e4b | D3: llama3.3-70b
A4: Fields in the manual annotation (what the PDF supports) | B4: =COUNTA('Reference (JSON)'!$B$2:$B$135) | C4: =COUNTA('Reference (JSON)'!$B$2:$B$135) | D4: =COUNTA('Reference (JSON)'!$B$2:$B$135)
A5: Fields the model output | B5: =COUNTIF('sample14-llama3.1-8b'!$D:$D,"Correct")+COUNTIF('sample14-llama3.1-8b'!$D:$D,"Hallucinated") | C5: =COUNTIF('sample14-gemma4-e4b'!$D:$D,"Correct")+COUNTIF('sample14-gemma4-e4b'!$D:$D,"Hallucinated") | D5: =COUNTIF('sample14-version1-llama3.3-70b'!$D:$D,"Correct")+COUNTIF('sample14-version1-llama3.3-70b'!$D:$D,"Hallucinated")
A6: Correct | B6: =COUNTIF('sample14-llama3.1-8b'!$D:$D,"Correct") | C6: =COUNTIF('sample14-gemma4-e4b'!$D:$D,"Correct") | D6: =COUNTIF('sample14-version1-llama3.3-70b'!$D:$D,"Correct")
A7: Hallucinated | B7: =COUNTIF('sample14-llama3.1-8b'!$D:$D,"Hallucinated") | C7: =COUNTIF('sample14-gemma4-e4b'!$D:$D,"Hallucinated") | D7: =COUNTIF('sample14-version1-llama3.3-70b'!$D:$D,"Hallucinated")
A8: Missed (in the PDF, not extracted) | B8: =COUNTIF('sample14-llama3.1-8b'!$D:$D,"Missed") | C8: =COUNTIF('sample14-gemma4-e4b'!$D:$D,"Missed") | D8: =COUNTIF('sample14-version1-llama3.3-70b'!$D:$D,"Missed")
A9: Total (Correct + Hallucinated + Missed) | B9: =B6+B7+B8 | C9: =C6+C7+C8 | D9: =D6+D7+D8
A11: Shares for the slide bar (of the total above)
A12: Correct % | B12: =IFERROR(B6/B9,0) | C12: =IFERROR(C6/C9,0) | D12: =IFERROR(D6/D9,0)
A13: Hallucinated % | B13: =IFERROR(B7/B9,0) | C13: =IFERROR(C7/C9,0) | D13: =IFERROR(D7/D9,0)
A14: Missed % | B14: =IFERROR(B8/B9,0) | C14: =IFERROR(C8/C9,0) | D14: =IFERROR(D8/D9,0)
A16: Precision, recall, F1
A17: Precision = Correct / Fields the model output | B17: =IFERROR(B6/B5,0) | C17: =IFERROR(C6/C5,0) | D17: =IFERROR(D6/D5,0)
A18: Recall = (Fields in reference - Missed) / Fields in reference | B18: =IFERROR((B4-B8)/B4,0) | C18: =IFERROR((C4-C8)/C4,0) | D18: =IFERROR((D4-D8)/D4,0)
A19: F1 = 2 x Precision x Recall / (Precision + Recall) | B19: =IFERROR(2*B17*B18/(B17+B18),0) | C19: =IFERROR(2*C17*C18/(C17+C18),0) | D19: =IFERROR(2*D17*D18/(D17+D18),0)
A21: Revised 2026-10-02 from the current reference JSON (134 fields) and model outputs, using the verdicts of notebooks/evaluate-rda-json.ipynb.
A22: Every number on this sheet is a formula over the per-model sheets and 'Reference (JSON)'. Per-model sheets now also list Missed reference fields (gray); Hallucinated keeps the original orange.
